Workbook

Sheet DATA
B1: ID | C1: Title | D1: Year | E1: Age | F1: Rotten Tomatoes | G1: Netflix | H1: Hulu | I1: Prime Video | J1: Disney+ | K1: Type | L1: RT Score | M1: Platform Count
A2: 0 | B2: 1 | C2: The Irishman | D2: 2019 | E2: 18+ | F2: 98/100 | G2: 1 | H2: 0 | I2: 0 | J2: 0 | K2: 0 | L2: =IFERROR(VALUE(LEFT(F2,FIND("/",F2)-1))/10,"") -> 9.8 | M2: =SUM(G2:J2) -> 1
A3: 1 | B3: 2 | C3: Dangal | D3: 2016 | E3: 7+ | F3: 97/100 | G3: 1 | H3: 0 | I3: 0 | J3: 0 | K3: 0 | L3: =IFERROR(VALUE(LEFT(F3,FIND("/",F3)-1))/10,"") -> 9.7 | M3: =SUM(G3:J3) -> 1
A4: 2 | B4: 3 | C4: David Attenborough: A Life on Our Planet | D4: 2020 | E4: 7+ | F4: 95/100 | G4: 1 | H4: 0 | I4: 0 | J4: 0 | K4: 0 | L4: =IFERROR(VALUE(LEFT(F4,FIND("/",F4)-1))/10,"") -> 9.5 | M4: =SUM(G4:J4) -> 1
A5: 3 | B5: 4 | C5: Lagaan: Once Upon a Time in India | D5: 2001 | E5: 7+ | F5: 94/100 | G5: 1 | H5: 0 | I5: 0 | J5: 0 | K5: 0 | L5: =IFERROR(VALUE(LEFT(F5,FIND("/",F5)-1))/10,"") -> 9.4 | M5: =SUM(G5:J5) -> 1
A6: 4 | B6: 5 | C6: Roma | D6: 2018 | E6: 18+ | F6: 94/100 | G6: 1 | H6: 0 | I6: 0 | J6: 0 | K6: 0 | L6: =IFERROR(VALUE(LEFT(F6,FIND("/",F6)-1))/10,"") -> 9.4 | M6: =SUM(G6:J6) -> 1
A7: 5 | B7: 6 | C7: To All the Boys I've Loved Before | D7: 2018 | E7: 13+ | F7: 94/100 | G7: 1 | H7: 0 | I7: 0 | J7: 0 | K7: 0 | L7: =IFERROR(VALUE(LEFT(F7,FIND("/",F7)-1))/10,"") -> 9.4 | M7: =SUM(G7:J7) -> 1
A8: 6 | B8: 7 | C8: The Social Dilemma | D8: 2020 | E8: 13+ | F8: 93/100 | G8: 1 | H8: 0 | I8: 0 | J8: 0 | K8: 0 | L8: =IFERROR(VALUE(LEFT(F8,FIND("/",F8)-1))/10,"") -> 9.3 | M8: =SUM(G8:J8) -> 1
A9: 7 | B9: 8 | C9: Okja | D9: 2017 | E9: 13+ | F9: 92/100 | G9: 1 | H9: 0 | I9: 0 | J9: 0 | K9: 0 | L9: =IFERROR(VALUE(LEFT(F9,FIND("/",F9)-1))/10,"") -> 9.2 | M9: =SUM(G9:J9) -> 1
A10: 8 | B10: 9 | C10: The Ballad of Buster Scruggs | D10: 2018 | E10: 16+ | F10: 92/100 | G10: 1 | H10: 0 | I10: 0 | J10: 0 | K10: 0 | L10: =IFERROR(VALUE(LEFT(F10,FIND("/",F10)-1))/10,"") -> 9.2 | M10: =SUM(G10:J10) -> 1
A11: 9 | B11: 10 | C11: The Trial of the Chicago 7 | D11: 2020 | E11: 18+ | F11: 92/100 | G11: 1 | H11: 0 | I11: 0 | J11: 0 | K11: 0 | L11: =IFERROR(VALUE(LEFT(F11,FIND("/",F11)-1))/10,"") -> 9.2 | M11: =SUM(G11:J11) -> 1
A12: 10 | B12: 11 | C12: Article 15 | D12: 2019 | E12: 18+ | F12: 92/100 | G12: 1 | H12: 0 | I12: 0 | J12: 0 | K12: 0 | L12: =IFERROR(VALUE(LEFT(F12,FIND("/",F12)-1))/10,"") -> 9.2 | M12: =SUM(G12:J12) -> 1
A13: 11 | B13: 12 | C13: Jim & Andy: The Great Beyond- Featuring a Very Special, Contractually Obligated Mention of Tony Clifton | D13: 2017 | E13: 18+ | F13: 92/100 | G13: 1 | H13: 0 | I13: 0 | J13: 0 | K13: 0 | L13: =IFERROR(VALUE(LEFT(F13,FIND("/",F13)-1))/10,"") -> 9.2 | M13: =SUM(G13:J13) -> 1
... A36: 34 | B36: 35 | C36: Gerald's Game | D36: 2017 | E36: 18+ | F36: 88/100 | G36: 1 | H36: 0 | I36: 0 | J36: 0 | K36: 0 | L36: =IFERROR(VALUE(LEFT(F36,FIND("/",F36)-1))/10,"") -> 8.8 | M36: =SUM(G36:J36) -> 1
A37: 35 | B37: 36 | C37: On Body and Soul | D37: 2017 | F37: 88/100 | G37: 1 | H37: 0 | I37: 0 | J37: 0 | K37: 0 | L37: =IFERROR(VALUE(LEFT(F37,FIND("/",F37)-1))/10,"") -> 8.8 | M37: =SUM(G37:J37) -> 1
A38: 36 | B38: 37 | C38: Shutter Island | D38: 2010 | E38: 18+ | F38: 88/100 | G38: 1 | H38: 0 | I38: 0 | J38: 0 | K38: 0 | L38: =IFERROR(VALUE(LEFT(F38,FIND("/",F38)-1))/10,"") -> 8.8 | M38: =SUM(G38:J38) -> 1
A39: 37 | B39: 38 | C39: Always Be My Maybe | D39: 2019 | E39: 13+ | F39: 88/100 | G39: 1 | H39: 0 | I39: 0 | J39: 0 | K39: 0 | L39: =IFERROR(VALUE(LEFT(F39,FIND("/",F39)-1))/10,"") -> 8.8 | M39: =SUM(G39:J39) -> 1
A40: 38 | B40: 39 | C40: The Intouchables | D40: 2011 | E40: 7+ | F40: 88/100 | G40: 1 | H40: 0 | I40: 0 | J40: 0 | K40: 0 | L40: =IFERROR(VALUE(LEFT(F40,FIND("/",F40)-1))/10,"") -> 8.8 | M40: =SUM(G40:J40) -> 1
A41: 39 | B41: 40 | C41: Bill Burr: Paper Tiger | D41: 2019 | E41: 18+ | F41: 87/100 | G41: 1 | H41: 0 | I41: 0 | J41: 0 | K41: 0 | L41: =IFERROR(VALUE(LEFT(F41,FIND("/",F41)-1))/10,"") -> 8.7 | M41: =SUM(G41:J41) -> 1
A42: 40 | B42: 41 | C42: Special 26 | D42: 2013 | F42: 87/100 | G42: 1 | H42: 0 | I42: 0 | J42: 0 | K42: 0 | L42: =IFERROR(VALUE(LEFT(F42,FIND("/",F42)-1))/10,"") -> 8.7 | M42: =SUM(G42:J42) -> 1
A43: 41 | B43: 42 | C43: Kiss the Ground | D43: 2020 | E43: 18+ | F43: 87/100 | G43: 1 | H43: 0 | I43: 0 | J43: 0 | K43: 0 | L43: =IFERROR(VALUE(LEFT(F43,FIND("/",F43)-1))/10,"") -> 8.7 | M43: =SUM(G43:J43) -> 1
A44: 42 | B44: 43 | C44: Crip Camp: A Disability Revolution | D44: 2020 | E44: 18+ | F44: 87/100 | G44: 1 | H44: 0 | I44: 0 | J44: 0 | K44: 0 | L44: =IFERROR(VALUE(LEFT(F44,FIND("/",F44)-1))/10,"") -> 8.7 | M44: =SUM(G44:J44) -> 1
A45: 43 | B45: 44 | C45: Extraction | D45: 2020 | E45: 18+ | F45: 87/100 | G45: 1 | H45: 0 | I45: 0 | J45: 0 | K45: 0 | L45: =IFERROR(VALUE(LEFT(F45,FIND("/",F45)-1))/10,"") -> 8.7 | M45: =SUM(G45:J45) -> 1
A46: 44 | B46: 45 | C46: No Direction Home: Bob Dylan | D46: 2005 | E46: all | F46: 87/100 | G46: 1 | H46: 0 | I46: 0 | J46: 0 | K46: 0 | L46: =IFERROR(VALUE(LEFT(F46,FIND("/",F46)-1))/10,"") -> 8.7 | M46: =SUM(G46:J46) -> 1
A47: 45 | B47: 46 | C47: Kabhi Khushi Kabhie Gham | D47: 2001 | E47: all | F47: 87/100 | G47: 1 | H47: 0 | I47: 0 | J47: 0 | K47: 0 | L47: =IFERROR(VALUE(LEFT(F47,FIND("/",F47)-1))/10,"") -> 8.7 | M47: =SUM(G47:J47) -> 1
A48: 46 | B48: 47 | C48: His House | D48: 2020 | E48: 16+ | F48: 87/100 | G48: 1 | H48: 0 | I48: 0 | J48: 0 | K48: 0 | L48: =IFERROR(VALUE(LEFT(F48,FIND("/",F48)-1))/10,"") -> 8.7 | M48: =SUM(G48:J48) -> 1
A49: 47 | B49: 48 | C49: Super Deluxe | D49: 2019 | E49: 18+ | F49: 87/100 | G49: 1 | H49: 0 | I49: 0 | J49: 0 | K49: 0 | L49: =IFERROR(VALUE(LEFT(F49,FIND("/",F49)-1))/10,"") -> 8.7 | M49: =SUM(G49:J49) -> 1
A50: 48 | B50: 49 | C50: The Guernsey Literary & Potato Peel Pie Society | D50: 2018 | E50: 16+ | F50: 87/100 | G50: 1 | H50: 0 | I50: 0 | J50: 0 | K50: 0 | L50: =IFERROR(VALUE(LEFT(F50,FIND("/",F50)-1))/10,"") -> 8.7 | M50: =SUM(G50:J50) -> 1
A51: 49 | B51: 50 | C51: A Secret Love | D51: 2020 | E51: 18+ | F51: 87/100 | G51: 1 | H51: 0 | I51: 0 | J51: 0 | K51: 0 | L51: =IFERROR(VALUE(LEFT(F51,FIND("/",F51)-1))/10,"") -> 8.7 | M51: =SUM(G51:J51) -> 1
A52: 50 | B52: 51 | C52: The Night Comes for Us | D52: 2018 | E52: 18+ | F52: 87/100 | G52: 1 | H52: 0 | I52: 0 | J52: 0 | K52: 0 | L52: =IFERROR(VALUE(LEFT(F52,FIND("/",F52)-1))/10,"") -> 8.7 | M52: =SUM(G52:J52) -> 1
A53: 51 | B53: 52 | C53: The Big Lebowski | D53: 1998 | E53: 18+ | F53: 87/100 | G53: 1 | H53: 0 | I53: 0 | J53: 0 | K53: 0 | L53: =IFERROR(VALUE(LEFT(F53,FIND("/",F53)-1))/10,"") -> 8.7 | M53: =SUM(G53:J53) -> 1
A54: 52 | B54: 53 | C54: Pad Man | D54: 2018 | E54: 13+ | F54: 87/100 | G54: 1 | H54: 0 | I54: 0 | J54: 0 | K54: 0 | L54: =IFERROR(VALUE(LEFT(F54,FIND("/",F54)-1))/10,"") -> 8.7 | M54: =SUM(G54:J54) -> 1
... A58: 56 | B58: 57 | C58: 3 Idiots | D58: 2009 | E58: 13+ | F58: 86/100 | G58: 1 | H58: 0 | I58: 0 | J58: 0 | K58: 0 | L58: =IFERROR(VALUE(LEFT(F58,FIND("/",F58)-1))/10,"") -> 8.6 | M58: =SUM(G58:J58) -> 1
A59: 57 | B59: 58 | C59: The Distinguished Citizen | D59: 2016 | F59: 86/100 | G59: 1 | H59: 0 | I59: 0 | J59: 0 | K59: 0 | L59: =IFERROR(VALUE(LEFT(F59,FIND("/",F59)-1))/10,"") -> 8.6 | M59: =SUM(G59:J59) -> 1
A60: 58 | B60: 59 | C60: A Shaun the Sheep Movie: Farmageddon | D60: 2019 | E60: all | F60: 86/100 | G60: 1 | H60: 0 | I60: 0 | J60: 0 | K60: 0 | L60: =IFERROR(VALUE(LEFT(F60,FIND("/",F60)-1))/10,"") -> 8.6 | M60: =SUM(G60:J60) -> 1
A61: 59 | B61: 60 | C61: A Clockwork Orange | D61: 1971 | E61: 18+ | F61: 86/100 | G61: 1 | H61: 0 | I61: 0 | J61: 0 | K61: 0 | L61: =IFERROR(VALUE(LEFT(F61,FIND("/",F61)-1))/10,"") -> 8.6 | M61: =SUM(G61:J61) -> 1
A62: 60 | B62: 61 | C62: What Happened to Monday | D62: 2017 | E62: 18+ | F62: 86/100 | G62: 1 | H62: 0 | I62: 0 | J62: 0 | K62: 0 | L62: =IFERROR(VALUE(LEFT(F62,FIND("/",F62)-1))/10,"") -> 8.6 | M62: =SUM(G62:J62) -> 1
A63: 61 | B63: 62 | C63: Anthony Jeselnik: Thoughts and Prayers | D63: 2015 | E63: 18+ | F63: 86/100 | G63: 1 | H63: 0 | I63: 0 | J63: 0 | K63: 0 | L63: =IFERROR(VALUE(LEFT(F63,FIND("/",F63)-1))/10,"") -> 8.6 | M63: =SUM(G63:J63) -> 1
A64: 62 | B64: 63 | C64: The White Helmets | D64: 2016 | E64: 16+ | F64: 86/100 | G64: 1 | H64: 0 | I64: 0 | J64: 0 | K64: 0 | L64: =IFERROR(VALUE(LEFT(F64,FIND("/",F64)-1))/10,"") -> 8.6 | M64: =SUM(G64:J64) -> 1
A65: 63 | B65: 64 | C65: Invader ZIM: Enter the Florpus | D65: 2019 | E65: 7+ | F65: 86/100 | G65: 1 | H65: 0 | I65: 0 | J65: 0 | K65: 0 | L65: =IFERROR(VALUE(LEFT(F65,FIND("/",F65)-1))/10,"") -> 8.6 | M65: =SUM(G65:J65) -> 1
...

Sheet DASHBOARD
A2: OTT MOVIE STREAMING ANALYTICS DASHBOARD
A3: DAV Lab Assignment 2 | Formula-based Excel analysis
A6: 1. Dataset Profile | O6: 7. Movies Released by Year
O7: Years | R7: Movies
A8: Total number of records | D8: =COUNTA(DATA!C2:C9516) -> 9515 | O8: 2019 | R8: {=SUMPRODUCT(--(DATA!D2:D9516&""=A2&""))} -> 0
A9: Total number of columns | D9: =COLUMNS(A1:K1) -> 11 | O9: 2020 | R9: {=SUMPRODUCT(--(DATA!D3:D9517&""=A3&""))} -> 0
A10: Earliest movie year | D10: =_xlfn.MINIFS(DATA!D2:D9516,DATA!D2:D9516,">0") -> 1914 | O10: 2021 | R10: {=SUMPRODUCT(--(DATA!D4:D9518&""=A4&""))} -> 2
A11: Latest movie year | D11: =MAX(DATA!D2:D9516) -> 2021 | O11: 2022 | R11: {=SUMPRODUCT(--(DATA!D5:D9519&""=A5&""))} -> 3
A12: Average movie year | D12: =AVERAGEIFS(DATA!D2:D9516,DATA!D2:D9516,">0") -> 2007.4224 | O12: 2023 | R12: {=SUMPRODUCT(--(DATA!D6:D9520&""=A6&""))} -> 0
A13: Missing Age | D13: =COUNTBLANK(DATA!E2:E9516) -> 4177
A14: Missing Rotten Tomatoes | D14: =COUNTBLANK(DATA!F2:F9516) -> 7
A17: 2. Rotten Tomatoes Score
A19: Average Rating | D19: =AVERAGE(DATA!L2:L9516) -> 5.3545015
A20: Highest Rating | D20: =MAX(DATA!L2:L9516) -> 9.8
A21: Lowest Rating | D21: =MIN(DATA!L2:L9516) -> 1
A22: Movies rated 8+ | D22: =COUNTIF(DATA!L2:L9516,">=8") -> 335
A25: 3. Streaming Platforms
A26: Platforms | D26: Movies
A27: Netflix | D27: =COUNTIF(DATA!G2:G9516,1) -> 3695
A28: Hulu | D28: =COUNTIF(DATA!H2:H9516,1) -> 1047
A29: Prime Video | D29: =COUNTIF(DATA!I2:I9516,1) -> 4113
A30: Disney+ | D30: =COUNTIF(DATA!J2:J9516,1) -> 922
A33: 4. Platform Percentage
A34: Platforms | D34: Percent
A35: Netflix | D35: =COUNTIF(DATA!G2:G9516,1)/COUNTA(DATA!C2:C9516) -> 0.38833421
A36: Hulu | D36: =COUNTIF(DATA!H2:H9516,1)/COUNTA(DATA!C2:C9516) -> 0.11003678
A37: Prime Video | D37: =COUNTIF(DATA!I2:I9516,1)/COUNTA(DATA!C2:C9516) -> 0.43226484
A38: Disney+ | D38: =COUNTIF(DATA!J2:J9516,1)/COUNTA(DATA!C2:C9516) -> 0.096899632
A46: 5. Rating Distribution
A47: Rating | C47: Movies
A48: 0–2 | C48: =COUNTIFS(DATA!L2:L9516,">=0",DATA!L2:L9516,"<2") -> 119
A49: 2–4 | C49: =COUNTIFS(DATA!L2:L9516,">=2",DATA!L2:L9516,"<4") -> 1036
A50: 4–6 | C50: =COUNTIFS(DATA!L2:L9516,">=4",DATA!L2:L9516,"<6") -> 5429
A51: 6–8 | C51: =COUNTIFS(DATA!L2:L9516,">=6",DATA!L2:L9516,"<8") -> 2589
A52: 8–10 | C52: =COUNTIFS(DATA!L2:L9516,">=8",DATA!L2:L9516,"<=10") -> 335
A59: 6. Age Rating
A60: Age | C60: Count
A61: 18+ | C61: =COUNTIF(DATA!E2:E9516,"18+") -> 2276
A62: 16+ | C62: =COUNTIF(DATA!E2:E9516,"16+") -> 276
A63: 13+ | C63: =COUNTIF(DATA!E2:E9516,"13+") -> 998
...
